Traceback (most recent call last):
  File "/opt/hostedtoolcache/Python/3.10.17/x64/lib/python3.10/site-packages/jupyter_core/utils/__init__.py", line 154, in wrapped
    asyncio.get_running_loop()
RuntimeError: no running event loop

During handling of the above exception, another exception occurred:

Traceback (most recent call last):
  File "/opt/hostedtoolcache/Python/3.10.17/x64/lib/python3.10/site-packages/jupyter_cache/executors/utils.py", line 58, in single_nb_execution
    executenb(
  File "/opt/hostedtoolcache/Python/3.10.17/x64/lib/python3.10/site-packages/nbclient/client.py", line 1319, in execute
    return NotebookClient(nb=nb, resources=resources, km=km, **kwargs).execute()
  File "/opt/hostedtoolcache/Python/3.10.17/x64/lib/python3.10/site-packages/jupyter_core/utils/__init__.py", line 158, in wrapped
    return loop.run_until_complete(inner)
  File "/opt/hostedtoolcache/Python/3.10.17/x64/lib/python3.10/asyncio/base_events.py", line 649, in run_until_complete
    return future.result()
  File "/opt/hostedtoolcache/Python/3.10.17/x64/lib/python3.10/site-packages/nbclient/client.py", line 709, in async_execute
    await self.async_execute_cell(
  File "/opt/hostedtoolcache/Python/3.10.17/x64/lib/python3.10/site-packages/nbclient/client.py", line 1062, in async_execute_cell
    await self._check_raise_for_error(cell, cell_index, exec_reply)
  File "/opt/hostedtoolcache/Python/3.10.17/x64/lib/python3.10/site-packages/nbclient/client.py", line 918, in _check_raise_for_error
    raise CellExecutionError.from_cell_and_msg(cell, exec_reply_content)
nbclient.exceptions.CellExecutionError: An error occurred while executing the following cell:
------------------
def print_metrics_ray_train(
    loss: torch.Tensor, accuracy: torch.Tensor, epoch: int
) -> None:
    metrics = {"loss": loss.item(), "accuracy": accuracy.item(), "epoch": epoch}
    if ray.train.get_context().get_world_rank() == 0:
        print(metrics)
    return metrics
------------------


[0;31m---------------------------------------------------------------------------[0m
[0;31mNameError[0m                                 Traceback (most recent call last)
Cell [0;32mIn[1], line 2[0m
[1;32m      1[0m [38;5;28;01mdef[39;00m[38;5;250m [39m[38;5;21mprint_metrics_ray_train[39m(
[0;32m----> 2[0m     loss: [43mtorch[49m[38;5;241m.[39mTensor, accuracy: torch[38;5;241m.[39mTensor, epoch: [38;5;28mint[39m
[1;32m      3[0m ) [38;5;241m-[39m[38;5;241m>[39m [38;5;28;01mNone[39;00m:
[1;32m      4[0m     metrics [38;5;241m=[39m {[38;5;124m"[39m[38;5;124mloss[39m[38;5;124m"[39m: loss[38;5;241m.[39mitem(), [38;5;124m"[39m[38;5;124maccuracy[39m[38;5;124m"[39m: accuracy[38;5;241m.[39mitem(), [38;5;124m"[39m[38;5;124mepoch[39m[38;5;124m"[39m: epoch}
[1;32m      5[0m     [38;5;28;01mif[39;00m ray[38;5;241m.[39mtrain[38;5;241m.[39mget_context()[38;5;241m.[39mget_world_rank() [38;5;241m==[39m [38;5;241m0[39m:

[0;31mNameError[0m: name 'torch' is not defined

