Traceback (most recent call last):
  File "/opt/hostedtoolcache/Python/3.10.17/x64/lib/python3.10/site-packages/jupyter_core/utils/__init__.py", line 154, in wrapped
    asyncio.get_running_loop()
RuntimeError: no running event loop

During handling of the above exception, another exception occurred:

Traceback (most recent call last):
  File "/opt/hostedtoolcache/Python/3.10.17/x64/lib/python3.10/site-packages/jupyter_cache/executors/utils.py", line 58, in single_nb_execution
    executenb(
  File "/opt/hostedtoolcache/Python/3.10.17/x64/lib/python3.10/site-packages/nbclient/client.py", line 1319, in execute
    return NotebookClient(nb=nb, resources=resources, km=km, **kwargs).execute()
  File "/opt/hostedtoolcache/Python/3.10.17/x64/lib/python3.10/site-packages/jupyter_core/utils/__init__.py", line 158, in wrapped
    return loop.run_until_complete(inner)
  File "/opt/hostedtoolcache/Python/3.10.17/x64/lib/python3.10/asyncio/base_events.py", line 649, in run_until_complete
    return future.result()
  File "/opt/hostedtoolcache/Python/3.10.17/x64/lib/python3.10/site-packages/nbclient/client.py", line 709, in async_execute
    await self.async_execute_cell(
  File "/opt/hostedtoolcache/Python/3.10.17/x64/lib/python3.10/site-packages/nbclient/client.py", line 1062, in async_execute_cell
    await self._check_raise_for_error(cell, cell_index, exec_reply)
  File "/opt/hostedtoolcache/Python/3.10.17/x64/lib/python3.10/site-packages/nbclient/client.py", line 918, in _check_raise_for_error
    raise CellExecutionError.from_cell_and_msg(cell, exec_reply_content)
nbclient.exceptions.CellExecutionError: An error occurred while executing the following cell:
------------------
mnist_app = OnlineMNISTClassifier.options(
    num_replicas=4, # we can scale to up to 10 replicas on a single GPU
    ray_actor_options={"num_gpus": 0.1}, 
).bind(local_path="/mnt/cluster_storage/model.pt")
------------------


[0;31m---------------------------------------------------------------------------[0m
[0;31mNameError[0m                                 Traceback (most recent call last)
Cell [0;32mIn[1], line 1[0m
[0;32m----> 1[0m mnist_app [38;5;241m=[39m [43mOnlineMNISTClassifier[49m[38;5;241m.[39moptions(
[1;32m      2[0m     num_replicas[38;5;241m=[39m[38;5;241m4[39m, [38;5;66;03m# we can scale to up to 10 replicas on a single GPU[39;00m
[1;32m      3[0m     ray_actor_options[38;5;241m=[39m{[38;5;124m"[39m[38;5;124mnum_gpus[39m[38;5;124m"[39m: [38;5;241m0.1[39m}, 
[1;32m      4[0m )[38;5;241m.[39mbind(local_path[38;5;241m=[39m[38;5;124m"[39m[38;5;124m/mnt/cluster_storage/model.pt[39m[38;5;124m"[39m)

[0;31mNameError[0m: name 'OnlineMNISTClassifier' is not defined

